Workbook

Sheet Lisez-moi
A1: Carthago FinTech — Registres du SMSI
A2: Méthode, registre des risques, plan de traitement, déclaration d'applicabilité (SoA), indicateurs — étude de cas pédagogique, organisation fictive
A4: Ordre de travail | B4: 1) Méthode : validez les échelles et les seuils. 2) Risques : relisez la cotation proposée et sa justification, ajustez-la si besoin, ajoutez ou fusionnez des risques. 3) Traitement : relisez les actions proposées (responsables et délais à valider). 4) SoA : relisez les décisions proposées, ajustez justifications et états de mise en œuvre. 5) Indicateurs : fixez les cibles et suivez les valeurs.
A5: Cellules à compléter | B5: En-têtes dorés et cellules jaune clair. Texte bleu = valeur de paramétrage modifiable (onglet Méthode). Les autres cellules contiennent du texte ou des formules : ne pas les écraser.
A6: Ce qui est prérempli | B6: Risques : 12 scénarios (11 regroupant les écarts et un risque physique du siège), avec cotation et justification proposées. Traitement : 36 actions proposées. SoA : les 93 contrôles de l'Annexe A (intitulés de l'édition française) avec décision d'applicabilité proposée, justification, risques, actions et état de mise en œuvre estimé d'après le cas. Indicateurs : valeurs de départ tirées du cas quand elles existent.
A7: Hypothèses | B7: Les échelles 1 à 4, les seuils (critique ≥ 12, élevé ≥ 8, modéré ≥ 4) et le seuil d'acceptation (≤ 3) sont des propositions de départ. Selon la clause 6.1.2, les critères d'acceptation des risques doivent être établis et validés par la direction : à documenter dans votre rapport. Les scénarios de risque et les cibles d'indicateurs sont des hypothèses à justifier.
A8: Droits d'auteur | B8: Ce fichier ne reproduit que les intitulés des contrôles, pas le texte de la norme. La norme ISO/IEC 27001:2022 est protégée : ne la publiez pas.

Sheet Méthode
A1: Méthode d'appréciation des risques (proposition)
A2: Inspirée de l'approche ISO/IEC 27005 : niveau de risque = vraisemblance × impact. À faire valider (clause 6.1.2 a).
A4: Échelle de vraisemblance
A5: Niveau | B5: Libellé | C5: Définition (proposition)
A6: 1 | B6: Rare | C6: Peu probable au cours des 12 prochains mois.
A7: 2 | B7: Possible | C7: Peut se produire environ une fois par an.
A8: 3 | B8: Probable | C8: Se produit plusieurs fois par an ou s'est déjà produit dans l'organisation.
A9: 4 | B9: Quasi certain | C9: Se produit en continu ou s'est produit plusieurs fois récemment.
A11: Échelle d'impact
A12: Niveau | B12: Libellé | C12: Définition (proposition)
A13: 1 | B13: Mineur | C13: Gêne limitée, sans effet visible pour les clients.
A14: 2 | B14: Modéré | C14: Dégradation de service ou fuite limitée, traitée en interne.
A15: 3 | B15: Majeur | C15: Interruption de service pour des clients, fuite de données sensibles ou obligation de notification.
A16: 4 | B16: Critique | C16: Interruption prolongée des paiements, fuite massive, sanction réglementaire ou perte d'un contrat majeur.
A18: Matrice des niveaux (calculée)
A19: Vraisemblance \ Impact | B19: 1 | C19: 2 | D19: 3 | E19: 4
A20: 1 | B20: =$A20*B$19 -> 1 | C20: =$A20*C$19 -> 2 | D20: =$A20*D$19 -> 3 | E20: =$A20*E$19 -> 4
A21: 2 | B21: =$A21*B$19 -> 2 | C21: =$A21*C$19 -> 4 | D21: =$A21*D$19 -> 6 | E21: =$A21*E$19 -> 8
A22: 3 | B22: =$A22*B$19 -> 3 | C22: =$A22*C$19 -> 6 | D22: =$A22*D$19 -> 9 | E22: =$A22*E$19 -> 12
A23: 4 | B23: =$A23*B$19 -> 4 | C23: =$A23*C$19 -> 8 | D23: =$A23*D$19 -> 12 | E23: =$A23*E$19 -> 16
A25: Seuils (modifiables)
A26: Seuil « Critique » (niveau ≥) | C26: 12
A27: Seuil « Élevé » (niveau ≥) | C27: 8
A28: Seuil « Modéré » (niveau ≥) | C28: 4
A29: Seuil d'acceptation (niveau ≤) | C29: 3
A31: Hypothèse : seuils proposés par l'auteure, à faire valider par la direction (critères d'acceptation, clause 6.1.2 a).

Sheet Risques
A1: Registre des risques
A2: Cotation proposée (échelles 1 à 4 de l'onglet Méthode), justifiée par des faits du cas. Les cotes résiduelles sont des cibles après traitement. Modifiez les colonnes dorées si vous n'êtes pas d'accord.
A4: ID risque | B4: Intitulé du risque | C4: Scénario (hypothèse : cause → événement → conséquence) | D4: Actifs concernés | E4: C / I / D | F4: Propriétaire du risque (rôle) | G4: Écarts liés | H4: Vraisemblance (1-4) | I4: Impact (1-4) | J4: Justification de la cotation | K4: Niveau brut | L4: Classe | M4: Décision | N4: Option de traitement | O4: Contrôles Annexe A visés | P4: Vraisemblance résiduelle (1-4) | Q4: Impact résiduel (1-4) | R4: Niveau résiduel | S4: Classe résiduelle | T4: Actions du plan | U4: Statut
A5: R-01 | B5: Compromission d'un compte privilégié | C5: Un attaquant obtient les identifiants d'un administrateur (phishing, fatigue MFA) ; des droits hérités et l'absence de PAM lui permettent d'agir sur Azure ; fuite, altération ou arrêt de services. | D5: Identités et habilitations ; Entra ID ; abonnements Azure ; secrets | E5: C, I, D | F5: CISO | G5: IAM-01 ; IAM-02 ; IAM-03 ; IAM-04 ; IAM-06 ; HUM-01 | H5: 3 | I5: 4 | J5: Vraisemblance 3 : l'événement s'est déjà produit le 3 sept. 2026 (§13) et ses causes (droits hérités, PAM en pilote) subsistent. Impact 4 : un rôle privilégié Azure peut toucher les données de transaction et la disponibilité de la plateforme ; l'incident a été classé majeur. Résiduel : l'accès à la demande et le MFA résistant au phishing rendent l'événement moins probable (2) et limitent l'étendue des droits (impact 3). | K5: =IF(OR(H5="",I5=""),"",H5*I5) -> 12 | L5: =IF(K5="","",IF(K5>=Méthode!$C$26,"Critique",IF(K5>=Méthode!$C$27,"Élevé",IF(K5>=Méthode!$C$28,"Modéré","Faible")))) -> Critique | M5: =IF(K5="","",IF(K5<=Méthode!$C$29,"Acceptable","À traiter")) -> À traiter | N5: Réduire | O5: A.5.16 ; A.5.18 ; A.8.2 ; A.8.5 ; A.6.3 | P5: 2 | Q5: 3 | R5: =IF(OR(P5="",Q5=""),"",P5*Q5) -> 6 | S5: =IF(R5="","",IF(R5>=Méthode!$C$26,"Critique",IF(R5>=Méthode!$C$27,"Élevé",IF(R5>=Méthode!$C$28,"Modéré","Faible")))) -> Modéré | T5: T-01 ; T-02 ; T-03 ; T-04 ; T-05 ; T-33 | U5: Évalué
A6: R-02 | B6: Détection et réponse tardives à une intrusion | C6: Des sources de logs non intégrées et un contrat MSSP non à jour retardent l'alerte et l'escalade ; l'attaquant reste actif plus longtemps. | D6: Logs de sécurité ; Sentinel ; Defender XDR ; contrat MSSP | E6: C, I, D | F6: CISO | G6: SOC-01 ; SOC-02 ; SOC-03 ; SOC-04 ; SOC-05 ; IAM-08 | H6: 3 | I6: 3 | J6: Vraisemblance 3 : l'alerte SIEM a été tardive le 3 sept. 2026 et des logs AKS et Entra ID n'étaient pas exploités en août 2026 (§12, §13). Impact 3 : une détection tardive allonge la présence de l'attaquant ; aucune exfiltration massive n'a été identifiée lors de l'incident. Résiduel : couverture des logs et contrat MSSP révisé réduisent la probabilité d'une détection tardive (2) ; l'impact potentiel d'une intrusion reste majeur (3). | K6: =IF(OR(H6="",I6=""),"",H6*I6) -> 9 | L6: =IF(K6="","",IF(K6>=Méthode!$C$26,"Critique",IF(K6>=Méthode!$C$27,"Élevé",IF(K6>=Méthode!$C$28,"Modéré","Faible")))) -> Élevé | M6: =IF(K6="","",IF(K6<=Méthode!$C$29,"Acceptable","À traiter")) -> À traiter | N6: Réduire | O6: A.8.15 ; A.8.16 ; A.5.24 ; A.5.25 ; A.5.26 ; A.5.22 | P6: 2 | Q6: 3 | R6: =IF(OR(P6="",Q6=""),"",P6*Q6) -> 6 | S6: =IF(R6="","",IF(R6>=Méthode!$C$26,"Critique",IF(R6>=Méthode!$C$27,"Élevé",IF(R6>=Méthode!$C$28,"Modéré","Faible")))) -> Modéré | T6: T-06 ; T-07 ; T-08 ; T-09 ; T-31 | U6: Évalué
A7: R-03 | B7: Comptes actifs non justifiés (départs, externes, mobilités) | C7: Un compte reste actif après un départ, une fin de mission ou un changement de fonction ; il est détourné ou abusé. | D7: Identités et habilitations | E7: C, I | F7: CISO | G7: IAM-01 ; IAM-02 ; IAM-09 | H7: 3 | I7: 3 | J7: Vraisemblance 3 : deux cas documentés en 2026, un compte de consultant actif 11 jours (avril) et un rôle hérité d'un ancien projet (sept.) ; aucun abus observé dans le premier cas. Impact 3 : un compte non justifié donne un accès non autorisé à des systèmes internes. Résiduel : automatisation des départs et mobilités et revue des accès réduisent la probabilité (2) ; l'impact potentiel reste majeur (3). | K7: =IF(OR(H7="",I7=""),"",H7*I7) -> 9 | L7: =IF(K7="","",IF(K7>=Méthode!$C$26,"Critique",IF(K7>=Méthode!$C$27,"Élevé",IF(K7>=Méthode!$C$28,"Modéré","Faible")))) -> Élevé | M7: =IF(K7="","",IF(K7<=Méthode!$C$29,"Acceptable","À traiter")) -> À traiter | N7: Réduire | O7: A.5.16 ; A.5.18 ; A.5.11 | P7: 2 | Q7: 3 | R7: =IF(OR(P7="",Q7=""),"",P7*Q7) -> 6 | S7: =IF(R7="","",IF(R7>=Méthode!$C$26,"Critique",IF(R7>=Méthode!$C$27,"Élevé",IF(R7>=Méthode!$C$28,"Modéré","Faible")))) -> Modéré | T7: T-10 ; T-11 | U7: Évalué
A8: R-04 | B8: Exposition de secrets et d'identifiants techniques | C8: Des secrets statiques ou présents dans d'anciens dépôts sont exploités pour accéder à des ressources. | D8: Clés, secrets, certificats ; code source et pipelines ; comptes de service | E8: C, I | F8: CTO | G8: IAM-07 ; DEV-04 | H8: 2 | I8: 4 | J8: Vraisemblance 2 : des secrets statiques subsistent et d'anciens dépôts ne sont pas assainis (§6, §7) ; aucune exploitation n'est constatée, mais des secrets ont dû être renouvelés après l'incident (§13). Impact 4 : les clés et secrets sont jugés critiques en confidentialité et intégrité (§5). Résiduel : secrets dans Key Vault avec rotation et dépôts assainis rendent l'exploitation peu probable (1) ; des identités managées limitent l'étendue d'un secret compromis (impact 3). | K8: =IF(OR(H8="",I8=""),"",H8*I8) -> 8 | L8: =IF(K8="","",IF(K8>=Méthode!$C$26,"Critique",IF(K8>=Méthode!$C$27,"Élevé",IF(K8>=Méthode!$C$28,"Modéré","Faible")))) -> Élevé | M8: =IF(K8="","",IF(K8<=Méthode!$C$29,"Acceptable","À traiter")) -> À traiter | N8: Réduire | O8: A.5.17 ; A.8.4 ; A.8.24 ; A.8.28 | P8: 1 | Q8: 3 | R8: =IF(OR(P8="",Q8=""),"",P8*Q8) -> 3 | S8: =IF(R8="","",IF(R8>=Méthode!$C$26,"Critique",IF(R8>=Méthode!$C$27,"Élevé",IF(R8>=Méthode!$C$28,"Modéré","Faible")))) -> Faible | T8: T-12 ; T-13 | U8: Évalué
A9: R-05 | B9: Mauvaise configuration cloud entraînant une exposition | C9: Une ressource Azure créée manuellement ou mal configurée expose des données ou des services. | D9: Azure ; stockage Blob ; données KYC | E9: C, I | F9: CIO | G9: CLD-01 ; CLD-02 | H9: 3 | I9: 3 | J9: Vraisemblance 3 : un conteneur de stockage mal configuré a été détecté en février 2026 (§12) et des ressources restent créées manuellement (§4). Impact 3 : des dossiers KYC sont stockés dans le stockage objet (§4) ; l'exposition de février était limitée. Résiduel : Azure Policy et IaC réduisent les écarts de configuration (2) ; l'impact potentiel sur des données KYC reste majeur (3). | K9: =IF(OR(H9="",I9=""),"",H9*I9) -> 9 | L9: =IF(K9="","",IF(K9>=Méthode!$C$26,"Critique",IF(K9>=Méthode!$C$27,"Élevé",IF(K9>=Méthode!$C$28,"Modéré","Faible")))) -> Élevé | M9: =IF(K9="","",IF(K9<=Méthode!$C$29,"Acceptable","À traiter")) -> À traiter | N9: Réduire | O9: A.8.9 ; A.8.3 ; A.5.23 ; A.8.32 | P9: 2 | Q9: 3 | R9: =IF(OR(P9="",Q9=""),"",P9*Q9) -> 6 | S9: =IF(R9="","",IF(R9>=Méthode!$C$26,"Critique",IF(R9>=Méthode!$C$27,"Élevé",IF(R9>=Méthode!$C$28,"Modéré","Faible")))) -> Modéré | T9: T-14 | U9: Évalué
A10: R-06 | B10: Mise en production de code vulnérable | C10: Des contrôles de sécurité non bloquants ou incomplets laissent passer une vulnérabilité exploitable ; changement urgent mal documenté. | D10: Code source et pipelines ; APIs ; portail commerçants | E10: C, I, D | F10: CTO | G10: DEV-01 ; DEV-02 ; DEV-03 ; CLD-04 | H10: 3 | I10: 3 | J10: Vraisemblance 3 : sur les applications historiques les résultats de scan créent un ticket sans bloquer le déploiement, le SAST couvre environ 80 % des dépôts (§7) ; hypothèse : des vulnérabilités atteignent donc régulièrement la production. Impact 3 : APIs et portail exposés à Internet. Résiduel : seuils de blocage homogènes et couverture complète réduisent la probabilité (2) ; l'exposition des APIs maintient un impact majeur (3). | K10: =IF(OR(H10="",I10=""),"",H10*I10) -> 9 | L10: =IF(K10="","",IF(K10>=Méthode!$C$26,"Critique",IF(K10>=Méthode!$C$27,"Élevé",IF(K10>=Méthode!$C$28,"Modéré","Faible")))) -> Élevé | M10: =IF(K10="","",IF(K10<=Méthode!$C$29,"Acceptable","À traiter")) -> À traiter | N10: Réduire | O10: A.8.25 ; A.8.28 ; A.8.29 ; A.8.8 ; A.8.32 | P10: 2 | Q10: 3 | R10: =IF(OR(P10="",Q10=""),"",P10*Q10) -> 6 | S10: =IF(R10="","",IF(R10>=Méthode!$C$26,"Critique",IF(R10>=Méthode!$C$27,"Élevé",IF(R10>=Méthode!$C$28,"Modéré","Faible")))) -> Modéré | T10: T-15 ; T-16 ; T-17 ; T-34 | U10: Évalué
A11: R-07 | B11: Indisponibilité prolongée de la plateforme de paiement | C11: Une panne ou un sinistre dépasse les RTO car le PRA n'a pas été testé de bout en bout et le BIA n'est pas à jour. | D11: API de paiement ; base de transactions ; sauvegardes | E11: D, I | F11: CIO | G11: CON-01 ; CON-02 ; CON-03 ; CON-04 ; CON-05 | H11: 2 | I11: 4 | J11: Vraisemblance 2 : aucune interruption majeure n'est rapportée, mais le test de juin 2026 a dépassé l'objectif (6 h 40 pour 4 h) et les tests de bascule sont irréguliers (§9). Impact 4 : une interruption empêche des centaines de commerçants d'encaisser et l'objectif de disponibilité est de 99,95 % (§1, §2). Résiduel : BIA validé et PRA éprouvé de bout en bout ramènent la durée d'une interruption dans les RTO (impact 3) ; la probabilité d'un sinistre reste inchangée (2). | K11: =IF(OR(H11="",I11=""),"",H11*I11) -> 8 | L11: =IF(K11="","",IF(K11>=Méthode!$C$26,"Critique",IF(K11>=Méthode!$C$27,"Élevé",IF(K11>=Méthode!$C$28,"Modéré","Faible")))) -> Élevé | M11: =IF(K11="","",IF(K11<=Méthode!$C$29,"Acceptable","À traiter")) -> À traiter | N11: Réduire | O11: A.5.29 ; A.5.30 ; A.8.13 ; A.8.14 | P11: 2 | Q11: 3 | R11: =IF(OR(P11="",Q11=""),"",P11*Q11) -> 6 | S11: =IF(R11="","",IF(R11>=Méthode!$C$26,"Critique",IF(R11>=Méthode!$C$27,"Élevé",IF(R11>=Méthode!$C$28,"Modéré","Faible")))) -> Modéré | T11: T-18 ; T-19 | U11: Évalué
A12: R-08 | B12: Défaillance d'un fournisseur critique ou de sa sécurité | C12: Azure, le MSSP, l'eKYC ou l'OTP subit un incident ou ne respecte pas les exigences ; des clauses d'audit, de sortie ou de sous-traitance manquent. | D12: Contrats ; services Azure, MSSP, eKYC, OTP | E12: C, I, D | F12: CISO | G12: FOU-01 ; FOU-02 ; FOU-03 ; FOU-04 ; SOC-04 | H12: 2 | I12: 4 | J12: Vraisemblance 2 : aucun incident fournisseur n'est rapporté, mais la grille d'évaluation n'est pas appliquée aux prestataires historiques et les contrats anciens sont hétérogènes (§10). Impact 4 : Azure et le MSSP sont jugés critiques pour la production, l'IAM technique et la détection (§10). Résiduel : évaluation, clauses contractuelles et plans de sortie limitent les conséquences d'une défaillance (impact 3) ; la probabilité dépend des tiers (2). | K12: =IF(OR(H12="",I12=""),"",H12*I12) -> 8 | L12: =IF(K12="","",IF(K12>=Méthode!$C$26,"Critique",IF(K12>=Méthode!$C$27,"Élevé",IF(K12>=Méthode!$C$28,"Modéré","Faible")))) -> Élevé | M12: =IF(K12="","",IF(K12<=Méthode!$C$29,"Acceptable","À traiter")) -> À traiter | N12: Réduire | O12: A.5.19 ; A.5.20 ; A.5.21 ; A.5.22 ; A.5.23 | P12: 2 | Q12: 3 | R12: =IF(OR(P12="",Q12=""),"",P12*Q12) -> 6 | S12: =IF(R12="","",IF(R12>=Méthode!$C$26,"Critique",IF(R12>=Méthode!$C$27,"Élevé",IF(R12>=Méthode!$C$28,"Modéré","Faible")))) -> Modéré | T12: T-20 ; T-21 | U12: Évalué
A13: R-09 | B13: Non-conformité réglementaire ou contractuelle | C13: Des exigences (BCT, protection des données, PCI DSS, éventuellement RGPD) ne sont pas identifiées ou respectées ; sanction ou perte de contrat. | D13: Contrats et procédures ; données personnelles | E13: C, I | F13: Risques & Conformité (DPO) | G13: LEG-01 ; LEG-02 ; LEG-03 | H13: 3 | I13: 3 | J13: Vraisemblance 3 : l'applicabilité des textes et de PCI DSS reste à analyser et aucun registre des exigences n'est mentionné (§11) ; hypothèse : des exigences non identifiées existent probablement. Impact 3 : sanction, perte d'un contrat de grand compte (§1) ou obligations non respectées. Résiduel : un registre des exigences tenu à jour rend une non-conformité non détectée rare (1) ; l'impact potentiel d'une sanction reste majeur (3). | K13: =IF(OR(H13="",I13=""),"",H13*I13) -> 9 | L13: =IF(K13="","",IF(K13>=Méthode!$C$26,"Critique",IF(K13>=Méthode!$C$27,"Élevé",IF(K13>=Méthode!$C$28,"Modéré","Faible")))) -> Élevé | M13: =IF(K13="","",IF(K13<=Méthode!$C$29,"Acceptable","À traiter")) -> À traiter | N13: Réduire | O13: A.5.31 ; A.5.34 ; A.5.36 | P13: 1 | Q13: 3 | R13: =IF(OR(P13="",Q13=""),"",P13*Q13) -> 3 | S13: =IF(R13="","",IF(R13>=Méthode!$C$26,"Critique",IF(R13>=Méthode!$C$27,"Élevé",IF(R13>=Méthode!$C$28,"Modéré","Faible")))) -> Faible | T13: T-22 | U13: Évalué
A14: R-10 | B14: Divulgation de données sensibles hors des circuits prévus | C14: Mauvaise classification, exports et documents partenaires non protégés, données de production dans des environnements non production. | D14: Données de transaction ; données KYC ; exports de reporting | E14: C | F14: CISO | G14: ACT-01 ; ACT-02 ; CLD-03 | H14: 3 | I14: 3 | J14: Vraisemblance 3 : la classification n'est pas appliquée uniformément aux exports et documents partenaires, l'inventaire n'est pas consolidé et des jeux de données issus de la production circulent en test (§5, §7, §12). Impact 3 : des données de transaction et KYC sont très sensibles en confidentialité (§5). Résiduel : marquage, règles de partage et masquage contrôlé réduisent la probabilité (2) ; la sensibilité des données maintient l'impact (3). | K14: =IF(OR(H14="",I14=""),"",H14*I14) -> 9 | L14: =IF(K14="","",IF(K14>=Méthode!$C$26,"Critique",IF(K14>=Méthode!$C$27,"Élevé",IF(K14>=Méthode!$C$28,"Modéré","Faible")))) -> Élevé | M14: =IF(K14="","",IF(K14<=Méthode!$C$29,"Acceptable","À traiter")) -> À traiter | N14: Réduire | O14: A.5.9 ; A.5.12 ; A.5.13 ; A.5.14 ; A.8.11 ; A.8.31 ; A.8.33 | P14: 2 | Q14: 3 | R14: =IF(OR(P14="",Q14=""),"",P14*Q14) -> 6 | S14: =IF(R14="","",IF(R14>=Méthode!$C$26,"Critique",IF(R14>=Méthode!$C$27,"Élevé",IF(R14>=Méthode!$C$28,"Modéré","Faible")))) -> Modéré | T14: T-23 ; T-24 ; T-25 ; T-35 | U14: Évalué
A15: R-11 | B15: Gouvernance du SMSI insuffisante | C15: Des rôles flous, des décisions non suivies et l'absence de pilotage (risques, audits, indicateurs) empêchent de démontrer la maîtrise des risques. | D15: SMSI ; politiques ; comité Cyber & Risques | E15: C, I, D | F15: CEO | G15: GOV-01 ; GOV-02 ; GOV-03 ; GOV-04 ; GOV-05 ; GOV-06 ; PIL-01 ; PIL-02 | H15: 4 | I15: 3 | J15: Vraisemblance 4 : la situation existe en continu (rôles non formalisés, suivi des décisions dispersé, §3 et §12). Impact 3 : la direction ne peut pas démontrer la maîtrise des risques (§13), ce qui menace la certification visée et les contrats de grands comptes. Résiduel : rôles approuvés, suivi centralisé et revue de direction réduisent la probabilité (2) ; l'impact devient modéré car les écarts seront détectés et traités (2). | K15: =IF(OR(H15="",I15=""),"",H15*I15) -> 12 | L15: =IF(K15="","",IF(K15>=Méthode!$C$26,"Critique",IF(K15>=Méthode!$C$27,"Élevé",IF(K15>=Méthode!$C$28,"Modéré","Faible")))) -> Critique | M15: =IF(K15="","",IF(K15<=Méthode!$C$29,"Acceptable","À traiter")) -> À traiter | N15: Réduire | O15: A.5.1 ; A.5.2 ; A.5.4 ; A.5.35 ; A.5.36 | P15: 2 | Q15: 2 | R15: =IF(OR(P15="",Q15=""),"",P15*Q15) -> 4 | S15: =IF(R15="","",IF(R15>=Méthode!$C$26,"Critique",IF(R15>=Méthode!$C$27,"Élevé",IF(R15>=Méthode!$C$28,"Modéré","Faible")))) -> Modéré | T15: T-26 ; T-27 ; T-28 ; T-29 ; T-30 ; T-32 | U15: Évalué
A16: R-12 | B16: Accès physique non autorisé ou perte d'équipement au siège | C16: Un accès non autorisé aux locaux, ou la perte ou le vol d'un poste d'administration ou d'un équipement réseau, expose des accès ou des données. | D16: Siège ; équipements réseau ; postes d'administration ; postes portables | E16: C, I | F16: CIO | G16: (aucun écart relevé dans le cas) | H16: 2 | I16: 2 | J16: Vraisemblance 2 : le siège ne contient que des équipements réseau, des services locaux limités et des postes d'administration (§4) ; aucun incident physique n'est rapporté. Impact 2 : la production est dans Azure ; un poste perdu serait protégé par l'EDR et le MFA mais reste un vecteur d'accès (hypothèse). Résiduel : contrôle d'accès aux locaux, chiffrement des postes et procédure de perte ou de vol réduisent la probabilité (1) ; l'impact reste modéré (2). | K16: =IF(OR(H16="",I16=""),"",H16*I16) -> 4 | L16: =IF(K16="","",IF(K16>=Méthode!$C$26,"Critique",IF(K16>=Méthode!$C$27,"Élevé",IF(K16>=Méthode!$C$28,"Modéré","Faible")))) -> Modéré | M16: =IF(K16="","",IF(K16<=Méthode!$C$29,"Acceptable","À traiter")) -> À traiter | N16: Réduire | O16: A.7.1 ; A.7.2 ; A.7.3 ; A.7.4 ; A.7.8 ; A.7.9 ; A.7.13 | P16: 1 | Q16: 2 | R16: =IF(OR(P16="",Q16=""),"",P16*Q16) -> 2 | S16: =IF(R16="","",IF(R16>=Méthode!$C$26,"Critique",IF(R16>=Méthode!$C$27,"Élevé",IF(R16>=Méthode!$C$28,"Modéré","Faible")))) -> Faible | T16: T-36 | U16: Évalué
K17: =IF(OR(H17="",I17=""),"",H17*I17) | L17: =IF(K17="","",IF(K17>=Méthode!$C$26,"Critique",IF(K17>=Méthode!$C$27,"Élevé",IF(K17>=Méthode!$C$28,"Modéré","Faible")))) | M17: =IF(K17="","",IF(K17<=Méthode!$C$29,"Acceptable","À traiter")) | R17: =IF(OR(P17="",Q17=""),"",P17*Q17) | S17: =IF(R17="","",IF(R17>=Méthode!$C$26,"Critique",IF(R17>=Méthode!$C$27,"Élevé",IF(R17>=Méthode!$C$28,"Modéré","Faible"))))
K18: =IF(OR(H18="",I18=""),"",H18*I18) | L18: =IF(K18="","",IF(K18>=Méthode!$C$26,"Critique",IF(K18>=Méthode!$C$27,"Élevé",IF(K18>=Méthode!$C$28,"Modéré","Faible")))) | M18: =IF(K18="","",IF(K18<=Méthode!$C$29,"Acceptable","À traiter")) | R18: =IF(OR(P18="",Q18=""),"",P18*Q18) | S18: =IF(R18="","",IF(R18>=Méthode!$C$26,"Critique",IF(R18>=Méthode!$C$27,"Élevé",IF(R18>=Méthode!$C$28,"Modéré","Faible"))))
K19: =IF(OR(H19="",I19=""),"",H19*I19) | L19: =IF(K19="","",IF(K19>=Méthode!$C$26,"Critique",IF(K19>=Méthode!$C$27,"Élevé",IF(K19>=Méthode!$C$28,"Modéré","Faible")))) | M19: =IF(K19="","",IF(K19<=Méthode!$C$29,"Acceptable","À traiter")) | R19: =IF(OR(P19="",Q19=""),"",P19*Q19) | S19: =IF(R19="","",IF(R19>=Méthode!$C$26,"Critique",IF(R19>=Méthode!$C$27,"Élevé",IF(R19>=Méthode!$C$28,"Modéré","Faible"))))
K20: =IF(OR(H20="",I20=""),"",H20*I20) | L20: =IF(K20="","",IF(K20>=Méthode!$C$26,"Critique",IF(K20>=Méthode!$C$27,"Élevé",IF(K20>=Méthode!$C$28,"Modéré","Faible")))) | M20: =IF(K20="","",IF(K20<=Méthode!$C$29,"Acceptable","À traiter")) | R20: =IF(OR(P20="",Q20=""),"",P20*Q20) | S20: =IF(R20="","",IF(R20>=Méthode!$C$26,"Critique",IF(R20>=Méthode!$C$27,"Élevé",IF(R20>=Méthode!$C$28,"Modéré","Faible"))))
K21: =IF(OR(H21="",I21=""),"",H21*I21) | L21: =IF(K21="","",IF(K21>=Méthode!$C$26,"Critique",IF(K21>=Méthode!$C$27,"Élevé",IF(K21>=Méthode!$C$28,"Modéré","Faible")))) | M21: =IF(K21="","",IF(K21<=Méthode!$C$29,"Acceptable","À traiter")) | R21: =IF(OR(P21="",Q21=""),"",P21*Q21) | S21: =IF(R21="","",IF(R21>=Méthode!$C$26,"Critique",IF(R21>=Méthode!$C$27,"Élevé",IF(R21>=Méthode!$C$28,"Modéré","Faible"))))
K22: =IF(OR(H22="",I22=""),"",H22*I22) | L22: =IF(K22="","",IF(K22>=Méthode!$C$26,"Critique",IF(K22>=Méthode!$C$27,"Élevé",IF(K22>=Méthode!$C$28,"Modéré","Faible")))) | M22: =IF(K22="","",IF(K22<=Méthode!$C$29,"Acceptable","À traiter")) | R22: =IF(OR(P22="",Q22=""),"",P22*Q22) | S22: =IF(R22="","",IF(R22>=Méthode!$C$26,"Critique",IF(R22>=Méthode!$C$27,"Élevé",IF(R22>=Méthode!$C$28,"Modéré","Faible"))))
K23: =IF(OR(H23="",I23=""),"",H23*I23) | L23: =IF(K23="","",IF(K23>=Méthode!$C$26,"Critique",IF(K23>=Méthode!$C$27,"Élevé",IF(K23>=Méthode!$C$28,"Modéré","Faible")))) | M23: =IF(K23="","",IF(K23<=Méthode!$C$29,"Acceptable","À traiter")) | R23: =IF(OR(P23="",Q23=""),"",P23*Q23) | S23: =IF(R23="","",IF(R23>=Méthode!$C$26,"Critique",IF(R23>=Méthode!$C$27,"Élevé",IF(R23>=Méthode!$C$28,"Modéré","Faible"))))
K24: =IF(OR(H24="",I24=""),"",H24*I24) | L24: =IF(K24="","",IF(K24>=Méthode!$C$26,"Critique",IF(K24>=Méthode!$C$27,"Élevé",IF(K24>=Méthode!$C$28,"Modéré","Faible")))) | M24: =IF(K24="","",IF(K24<=Méthode!$C$29,"Acceptable","À traiter")) | R24: =IF(OR(P24="",Q24=""),"",P24*Q24) | S24: =IF(R24="","",IF(R24>=Méthode!$C$26,"Critique",IF(R24>=Méthode!$C$27,"Élevé",IF(R24>=Méthode!$C$28,"Modéré","Faible"))))
K25: =IF(OR(H25="",I25=""),"",H25*I25) | L25: =IF(K25="","",IF(K25>=Méthode!$C$26,"Critique",IF(K25>=Méthode!$C$27,"Élevé",IF(K25>=Méthode!$C$28,"Modéré","Faible")))) | M25: =IF(K25="","",IF(K25<=Méthode!$C$29,"Acceptable","À traiter")) | R25: =IF(OR(P25="",Q25=""),"",P25*Q25) | S25: =IF(R25="","",IF(R25>=Méthode!$C$26,"Critique",IF(R25>=Méthode!$C$27,"Élevé",IF(R25>=Méthode!$C$28,"Modéré","Faible"))))
K26: =IF(OR(H26="",I26=""),"",H26*I26) | L26: =IF(K26="","",IF(K26>=Méthode!$C$26,"Critique",IF(K26>=Méthode!$C$27,"Élevé",IF(K26>=Méthode!$C$28,"Modéré","Faible")))) | M26: =IF(K26="","",IF(K26<=Méthode!$C$29,"Acceptable","À traiter")) | R26: =IF(OR(P26="",Q26=""),"",P26*Q26) | S26: =IF(R26="","",IF(R26>=Méthode!$C$26,"Critique",IF(R26>=Méthode!$C$27,"Élevé",IF(R26>=Méthode!$C$28,"Modéré","Faible"))))
K27: =IF(OR(H27="",I27=""),"",H27*I27) | L27: =IF(K27="","",IF(K27>=Méthode!$C$26,"Critique",IF(K27>=Méthode!$C$27,"Élevé",IF(K27>=Méthode!$C$28,"Modéré","Faible")))) | M27: =IF(K27="","",IF(K27<=Méthode!$C$29,"Acceptable","À traiter")) | R27: =IF(OR(P27="",Q27=""),"",P27*Q27) | S27: =IF(R27="","",IF(R27>=Méthode!$C$26,"Critique",IF(R27>=Méthode!$C$27,"Élevé",IF(R27>=Méthode!$C$28,"Modéré","Faible"))))
K28: =IF(OR(H28="",I28=""),"",H28*I28) | L28: =IF(K28="","",IF(K28>=Méthode!$C$26,"Critique",IF(K28>=Méthode!$C$27,"Élevé",IF(K28>=Méthode!$C$28,"Modéré","Faible")))) | M28: =IF(K28="","",IF(K28<=Méthode!$C$29,"Acceptable","À traiter")) | R28: =IF(OR(P28="",Q28=""),"",P28*Q28) | S28: =IF(R28="","",IF(R28>=Méthode!$C$26,"Critique",IF(R28>=Méthode!$C$27,"Élevé",IF(R28>=Méthode!$C$28,"Modéré","Faible"))))
... K60: =IF(OR(H60="",I60=""),"",H60*I60) | L60: =IF(K60="","",IF(K60>=Méthode!$C$26,"Critique",IF(K60>=Méthode!$C$27,"Élevé",IF(K60>=Méthode!$C$28,"Modéré","Faible")))) | M60: =IF(K60="","",IF(K60<=Méthode!$C$29,"Acceptable","À traiter")) | R60: =IF(OR(P60="",Q60=""),"",P60*Q60) | S60: =IF(R60="","",IF(R60>=Méthode!$C$26,"Critique",IF(R60>=Méthode!$C$27,"Élevé",IF(R60>=Méthode!$C$28,"Modéré","Faible"))))

Sheet Traitement
A1: Plan de traitement des risques
A2: Actions proposées pour réduire chaque risque ; échéances en mois à partir du lancement du projet (septembre 2026). Responsables et délais à valider avec les propriétaires de risques.
A4: ID action | B4: Risque (ID) | C4: Option | D4: Mesure / action à mettre en œuvre | E4: Contrôle(s) Annexe A | F4: Responsable (rôle) | G4: Échéance (mois du projet) | H4: Priorité | I4: Statut | J4: Indicateur de réussite
A5: T-01 | B5: R-01 | C5: Réduire | D5: Activer l'accès privilégié à la demande avec approbation pour tous les rôles Azure à privilèges et supprimer les rôles permanents hors comptes de secours. | E5: A.8.2 ; A.5.18 | F5: CIO | G5: Mois 3 | H5: Haute | I5: À planifier | J5: 0 rôle privilégié permanent hors comptes de secours
A6: T-02 | B6: R-01 | C6: Réduire | D6: Imposer une méthode MFA résistante au phishing (ou number matching) aux comptes d'administration, via l'accès conditionnel. | E6: A.8.5 ; A.5.17 | F6: CISO | G6: Mois 2 | H6: Haute | I6: À planifier | J6: 100 % des comptes d'administration concernés
A7: T-03 | B7: R-01 | C7: Réduire | D7: Mener une revue exceptionnelle des rôles Azure et retirer les droits hérités d'anciens projets. | E7: A.5.18 | F7: CIO | G7: Mois 1 | H7: Haute | I7: À planifier | J7: Revue terminée, écarts clos (KPI-03)
A8: T-04 | B8: R-01 | C8: Réduire | D8: Étendre les comptes d'administration dédiés à toutes les équipes et faire passer le PAM du pilote à la production. | E8: A.8.2 | F8: CIO | G8: Mois 6 | H8: Moyenne | I8: À planifier | J8: PAM en production, 100 % des administrateurs avec compte dédié
A9: T-05 | B9: R-01 | C9: Réduire | D9: Former les rôles à privilèges au phishing et à la fatigue MFA, puis simuler une campagne ciblée. | E9: A.6.3 | F9: CISO | G9: Mois 3 | H9: Haute | I9: À planifier | J9: 100 % des administrateurs formés ; taux de signalement suivi (KPI-10)
A10: T-06 | B10: R-02 | C10: Réduire | D10: Intégrer dans Sentinel les logs AKS, les événements Entra ID avancés et les journaux d'administration Azure. | E10: A.8.15 ; A.8.16 | F10: CISO | G10: Mois 2 | H10: Haute | I10: À planifier | J10: 100 % des sources critiques collectées (KPI-04)
A11: T-07 | B11: R-02 | C11: Réduire | D11: Exiger une revue des règles de détection à chaque changement d'architecture, intégrée à la gestion des changements. | E11: A.8.16 ; A.8.32 | F11: CISO | G11: Mois 3 | H11: Haute | I11: À planifier | J11: Aucun changement d'architecture clos sans revue de détection
A12: T-08 | B12: R-02 | C12: Réduire | D12: Réviser le contrat MSSP et son annexe : sources de logs, responsabilités, délais d'escalade. | E12: A.5.20 ; A.5.22 | F12: CISO | G12: Mois 4 | H12: Haute | I12: À planifier | J12: Annexe signée et alignée sur l'architecture actuelle
A13: T-09 | B13: R-02 | C13: Réduire | D13: Planifier deux exercices de crise par an dont un avec la Direction générale, et suivre les actions décidées. | E13: A.5.24 ; A.5.27 | F13: CISO | G13: Mois 6 | H13: Moyenne | I13: À planifier | J13: 2 exercices réalisés, actions closes (KPI-09)
A14: T-10 | B14: R-03 | C14: Réduire | D14: Automatiser les départs et mobilités, et révoquer les comptes externes à la date de fin de mission enregistrée. | E14: A.5.16 ; A.5.18 | F14: CIO | G14: Mois 5 | H14: Haute | I14: À planifier | J14: Délai de désactivation ≤ 1 jour (KPI-02)
A15: T-11 | B15: R-03 | C15: Réduire | D15: Fixer un calendrier unique de revues d'accès, semestrielles pour les systèmes critiques. | E15: A.5.18 | F15: CISO | G15: Mois 3 | H15: Moyenne | I15: À planifier | J15: 100 % des revues réalisées à temps (KPI-03)
... A40: T-36 | B40: R-12 | C40: Réduire | D40: Appliquer des mesures physiques proportionnées au siège : contrôle d'accès, surveillance, inventaire et maintenance des équipements réseau et des postes d'administration. | E40: A.7.1 ; A.7.2 ; A.7.3 ; A.7.4 ; A.7.8 ; A.7.13 | F40: CIO | G40: Mois 6 | H40: Moyenne | I40: À planifier | J40: Mesures en place et revues annuellement

Sheet SoA
A1: Déclaration d'applicabilité (SoA) — ISO/IEC 27001:2022, Annexe A
A2: 93 contrôles : décision proposée, justification, risques, écarts et actions liés, état de mise en œuvre estimé d'après le cas. À relire et valider avec les propriétaires de risques.
A3: Applicables : | B3: =COUNTIF(D7:D99,"Oui") -> 88 | C3: Non applicables : | D3: =COUNTIF(D7:D99,"Non") -> 5 | E3: Non renseignés : | F3: =COUNTA(A7:A99)-B3-D3 -> 0
A4: Implémentés : | B4: =COUNTIF(I7:I99,"Implémentée") -> 5 | C4: Partiels : | D4: =COUNTIF(I7:I99,"Partielle") -> 52 | E4: À planifier : | F4: =COUNTIF(I7:I99,"À planifier") -> 31
A6: ID | B6: Thème | C6: Intitulé du contrôle | D6: Applicable ? (Oui / Non) | E6: Justification | F6: Risque(s) lié(s) | G6: Écarts liés | H6: Actions du plan | I6: Mise en œuvre (estimée) | J6: Preuve / document attendu
A7: 5.1 | B7: Organisationnelles | C7: Politiques de sécurité de l'information | D7: Oui | E7: Exigence de la clause 5.2 ; politiques partiellement à jour (GOV-06). | F7: R-11 | G7: GOV-06 | H7: T-30 | I7: Partielle | J7: Politique générale de sécurité, historique des versions
A8: 5.2 | B8: Organisationnelles | C8: Fonctions et responsabilités liées à la sécurité de l'information | D8: Oui | E8: Rôles du SMSI non formalisés (GOV-01, GOV-03). | F8: R-11 | G8: GOV-01 ; GOV-03 | H8: T-26 | I8: Partielle | J8: Matrice RACI approuvée
A9: 5.3 | B9: Organisationnelles | C9: Séparation des tâches | D9: Oui | E9: Rôles transverses d'administrateurs entre environnements (IAM-03). | F9: R-01 | G9: IAM-03 | H9: T-33 | I9: Partielle | J9: Export des rôles Azure, règles de séparation des tâches
A10: 5.4 | B10: Organisationnelles | C10: Responsabilités de la direction | D10: Oui | E10: Comité Cyber & Risques irrégulier, suivi des décisions dispersé (GOV-02). | F10: R-11 | G10: GOV-01 ; GOV-02 | H10: T-26 ; T-27 | I10: Partielle | J10: Comptes rendus du comité, registre des décisions
A11: 5.5 | B11: Organisationnelles | C11: Contacts avec les autorités | D11: Oui | E11: Établissement de paiement soumis à la BCT, à l'INPDP et à l'ANCS (§11) : contacts utiles pour notifier un incident. | F11: R-09 | H11: T-31 | I11: À planifier | J11: Liste des contacts autorités, procédure de notification
A12: 5.6 | B12: Organisationnelles | C12: Contacts avec des groupes d'intérêt spécifiques | D12: Oui | E12: Les échanges avec des groupes sectoriels ou des CERT soutiennent la détection (R-02). | F12: R-02 | H12: T-31 | I12: À planifier | J12: Participation à des groupes d'échange
A13: 5.7 | B13: Organisationnelles | C13: Renseignement sur les menaces | D13: Oui | E13: Defender XDR et Sentinel produisent des alertes ; le renseignement sur les menaces est à structurer pour la détection (R-02). | F13: R-02 | H13: T-31 | I13: Partielle | J13: Sources de renseignement utilisées, règles de détection associées
A14: 5.8 | B14: Organisationnelles | C14: Sécurité de l'information dans la gestion de projet | D14: Oui | E14: Des migrations (Kubernetes) ont laissé des écarts de supervision et des droits hérités (SOC-04, IAM-03). | F14: R-01 ; R-02 | H14: T-34 | I14: À planifier | J14: Check-list de sécurité des projets
A15: 5.9 | B15: Organisationnelles | C15: Inventaire des informations et autres actifs associés | D15: Oui | E15: Inventaire des actifs informationnels non consolidé (ACT-01). | F15: R-10 | G15: ACT-01 | H15: T-25 | I15: Partielle | J15: CMDB, inventaire des actifs informationnels
A16: 5.10 | B16: Organisationnelles | C16: Utilisation correcte des informations et autres actifs associés | D16: Oui | E16: Politique d'usage acceptable publiée (§12) ; application à vérifier. | F16: R-10 | I16: Implémentée | J16: Politique d'usage acceptable, preuves de lecture
A17: 5.11 | B17: Organisationnelles | C17: Restitution des actifs | D17: Oui | E17: Restitution des actifs et des accès à la fin d'un contrat ou d'une mission (IAM-09). | F17: R-03 | H17: T-35 | I17: Partielle | J17: Check-list de départ, tickets de départ
A18: 5.12 | B18: Organisationnelles | C18: Classification des informations | D18: Oui | E18: Classification à quatre niveaux non appliquée uniformément (ACT-02). | F18: R-10 | G18: ACT-02 | H18: T-23 | I18: Partielle | J18: Politique de classification 2025, échantillon d'exports
A19: 5.13 | B19: Organisationnelles | C19: Marquage des informations | D19: Oui | E19: Marquage des exports et des documents partenaires incomplet (ACT-02). | F19: R-10 | G19: ACT-02 | H19: T-23 | I19: Partielle | J19: Exemples de documents marqués
A20: 5.14 | B20: Organisationnelles | C20: Transfert des informations | D20: Oui | E20: Échanges avec partenaires, banques et clients par exports et APIs (ACT-02). | F20: R-10 | G20: ACT-02 | H20: T-23 | I20: Partielle | J20: Règles de transfert, accords d'échange
A21: 5.15 | B21: Organisationnelles | C21: Contrôle d'accès | D21: Oui | E21: Contrôle par rôles (RBAC) et accès conditionnel en place, droits historiques accumulés (IAM-03). | F21: R-01 | G21: IAM-03 | H21: T-33 | I21: Partielle | J21: Politique d'accès, export RBAC
A22: 5.16 | B22: Organisationnelles | C22: Gestion des identités | D22: Oui | E22: Identités centralisées dans Entra ID ; mobilités et départs en partie manuels (IAM-01, IAM-09). | F22: R-01 ; R-03 | G22: IAM-01 ; IAM-07 ; IAM-09 | H22: T-10 | I22: Partielle | J22: Procédure JML, export Entra ID
A23: 5.17 | B23: Organisationnelles | C23: Informations d'authentification | D23: Oui | E23: Secrets statiques et rotation variable (IAM-07). | F23: R-04 | G23: IAM-06 ; IAM-07 ; DEV-04 | H23: T-02 ; T-12 | I23: Partielle | J23: Inventaire des secrets, dates de rotation
A24: 5.18 | B24: Organisationnelles | C24: Droits d'accès | D24: Oui | E24: Retrait des droits et revues d'accès hétérogènes (IAM-01, IAM-02). | F24: R-01 ; R-03 | G24: IAM-01 ; IAM-02 ; IAM-09 | H24: T-01 ; T-03 ; T-10 ; T-11 | I24: Partielle | J24: Comptes rendus de revues d'accès
A25: 5.19 | B25: Organisationnelles | C25: Sécurité de l'information dans les relations avec les fournisseurs | D25: Oui | E25: Grille d'évaluation non appliquée aux fournisseurs historiques (FOU-01). | F25: R-08 | G25: FOU-01 | H25: T-20 | I25: Partielle | J25: Grille d'évaluation, évaluations réalisées
A26: 5.20 | B26: Organisationnelles | C26: La sécurité de l'information dans les accords conclus avec les fournisseurs | D26: Oui | E26: Contrats anciens hétérogènes sur l'audit, la sortie et les sous-traitants (FOU-02, FOU-03). | F26: R-08 | G26: SOC-04 ; FOU-02 ; FOU-03 | H26: T-08 ; T-20 | I26: Partielle | J26: Contrats critiques, clauses types
A27: 5.21 | B27: Organisationnelles | C27: Gestion de la sécurité de l'information dans la chaîne d'approvisionnement des TIC | D27: Oui | E27: Dépendances logicielles et services TIC (DEV-03, FOU-04). | F27: R-08 ; R-06 | G27: DEV-03 ; FOU-01 ; FOU-04 | H27: T-21 | I27: Partielle | J27: Rapports SCA, liste des fournisseurs TIC
A28: 5.22 | B28: Organisationnelles | C28: Surveillance, révision et gestion des changements des services fournisseurs | D28: Oui | E28: Annexe du contrat MSSP non révisée (SOC-04). | F28: R-02 ; R-08 | G28: SOC-04 ; FOU-02 | H28: T-08 ; T-20 | I28: Partielle | J28: Revues de service des fournisseurs, SLA
A29: 5.23 | B29: Organisationnelles | C29: Sécurité de l'information dans l'utilisation de services en nuage | D29: Oui | E29: Azure est critique pour la production et l'IAM technique ; plan de sortie absent (§10, FOU-04). | F29: R-05 ; R-08 | G29: CLD-02 ; FOU-02 ; FOU-04 | H29: T-14 ; T-21 | I29: Partielle | J29: Modèle de responsabilité partagée, plan de sortie
... A33: 5.27 | B33: Organisationnelles | C33: Tirer des enseignements des incidents de sécurité de l'information | D33: Oui | E33: Actions de l'exercice de nov. 2025 suivies de façon dispersée (GOV-04). | F33: R-02 ; R-11 | G33: GOV-04 ; SOC-05 | H33: T-09 | I33: Partielle | J33: Retours d'expérience, plan d'actions
A34: 5.28 | B34: Organisationnelles | C34: Collecte de preuves | D34: Oui | E34: Les investigations s'appuient sur les journaux (§13) ; procédure de préservation des preuves non mentionnée. | F34: R-02 | H34: T-31 | I34: À planifier | J34: Procédure de collecte et de conservation des preuves
A35: 5.29 | B35: Organisationnelles | C35: Sécurité de l'information pendant une perturbation | D35: Oui | E35: Maintien de la sécurité pendant une perturbation à démontrer (CON-01). | F35: R-07 | G35: CON-01 | H35: T-18 | I35: Partielle | J35: PCA, PRA
A36: 5.30 | B36: Organisationnelles | C36: Préparation des TIC pour la continuité d'activité | D36: Oui | E36: RTO et RPO à valider, PRA testé de façon irrégulière (CON-02, CON-04). | F36: R-07 | G36: CON-01 ; CON-02 ; CON-03 ; CON-04 ; CON-05 | H36: T-18 ; T-19 | I36: Partielle | J36: BIA, PRA, rapports de tests
A37: 5.31 | B37: Organisationnelles | C37: Exigences légales, statutaires, réglementaires et contractuelles | D37: Oui | E37: Applicabilité des textes à analyser, pas de registre (LEG-01). | F37: R-09 | G37: GOV-03 ; LEG-01 ; LEG-02 ; LEG-03 | H37: T-22 | I37: À planifier | J37: Registre des exigences légales et contractuelles
A38: 5.32 | B38: Organisationnelles | C38: Droits de propriété intellectuelle | D38: Oui | E38: Développement logiciel avec des composants tiers : licences et droits à respecter. | F38: R-09 | H38: T-30 | I38: À planifier | J38: Inventaire des licences (SBOM)
A39: 5.33 | B39: Organisationnelles | C39: Protection des enregistrements | D39: Oui | E39: Journaux, contrats et preuves d'audit à protéger et conserver (§5). | F39: R-02 ; R-09 | H39: T-30 | I39: À planifier | J39: Règles de conservation, droits d'accès aux enregistrements
A40: 5.34 | B40: Organisationnelles | C40: Protection de la vie privée et des données à caractère personnel (DCP) | D40: Oui | E40: Données KYC et loi 2004-63 ; transferts à analyser (LEG-02). | F40: R-09 | G40: LEG-02 | H40: T-22 | I40: À planifier | J40: Registre des traitements, analyse du DPO
A41: 5.35 | B41: Organisationnelles | C41: Révision indépendante de la sécurité de l'information | D41: Oui | E41: Aucun audit interne ni revue indépendante mentionné (PIL-01). | F41: R-11 | G41: PIL-01 | H41: T-28 | I41: À planifier | J41: Programme d'audit interne
A42: 5.36 | B42: Organisationnelles | C42: Conformité aux politiques, règles et normes de sécurité de l'information | D42: Oui | E42: Vérification de la conformité aux politiques et aux exigences (LEG-01, PIL-01). | F42: R-09 ; R-11 | G42: LEG-01 ; LEG-03 ; PIL-01 | H42: T-22 ; T-28 | I42: À planifier | J42: Rapports de conformité
A43: 5.37 | B43: Organisationnelles | C43: Procédures d'exploitation documentées | D43: Oui | E43: Opérations manuelles d'administration et de maintenance (CLD-01). | F43: R-05 | H43: T-30 | I43: Partielle | J43: Procédures d'exploitation documentées
A44: 6.1 | B44: Personnes | C44: Sélection des candidats | D44: Oui | E44: Accès à des données financières et KYC (§5) : vérifications adaptées au rôle. | F44: R-10 | H44: T-32 | I44: À planifier | J44: Procédure de recrutement, vérifications effectuées
...

Sheet Indicateurs
A1: Indicateurs du SMSI (clause 9.1)
A2: Valeurs de départ tirées du cas quand elles existent. Les cibles sont des propositions à valider.
A4: ID | B4: Indicateur | C4: Objectif de sécurité lié | D4: Mode de calcul | E4: Source des données | F4: Fréquence | G4: Valeur de départ (cas) | H4: Cible (proposition) | I4: Valeur actuelle
A5: KPI-01 | B5: Couverture MFA des comptes humains | C5: Maîtriser les identités et les accès | D5: Comptes humains avec MFA ÷ comptes humains actifs | E5: Export Entra ID | F5: Mensuelle | G5: ≈ 94 % (§6) | H5: 100 % hors exceptions documentées
A6: KPI-02 | B6: Délai de désactivation d'un compte après départ ou fin de mission | C6: Maîtriser les identités et les accès | D6: Date de désactivation − date de fin (jours) | E6: Tickets RH / journaux Entra ID | F6: Mensuelle | G6: 11 jours pour un consultant (avril 2026, §6) | H6: ≤ 1 jour
A7: KPI-03 | B7: Revues d'accès réalisées dans les délais | C7: Maîtriser les identités et les accès | D7: Revues faites à temps ÷ revues planifiées | E7: Comptes rendus de revues | F7: Semestrielle | G7: Non mesuré (semestrielle sur quelques systèmes, §6) | H7: 100 % des systèmes critiques
A8: KPI-04 | B8: Couverture des sources de logs critiques dans Sentinel | C8: Améliorer la couverture de supervision | D8: Sources critiques collectées ÷ sources critiques identifiées | E8: Inventaire des sources / Sentinel | F8: Trimestrielle | G8: Non mesurée (logs AKS, Entra ID avancés, admin Azure incomplets, §8) | H8: 100 % des sources critiques
A9: KPI-05 | B9: Délai entre accès malveillant et blocage lors d'un incident P1 | C9: Améliorer la qualité de la réponse à incident | D9: Heure du blocage − heure de l'accès (minutes) | E9: Chronologie d'incident | F9: Par incident | G9: ≈ 59 min (19:06 → 20:05, Figure 4, à vérifier) | H9: À fixer avec le MSSP (SLA P1)
A10: KPI-06 | B10: Couverture SAST des dépôts actifs | C10: Sécuriser le cycle de développement | D10: Dépôts avec SAST ÷ dépôts actifs | E10: GitLab | F10: Mensuelle | G10: ≈ 80 % (§7, estimé) | H10: 100 %
A11: KPI-07 | B11: Temps de restauration comparé au RTO | C11: Aligner continuité et PRA sur le besoin métier | D11: Durée mesurée ÷ RTO documenté | E11: Rapports de tests de restauration | F11: À chaque test | G11: 6 h 40 pour un objectif de 4 h (juin 2026, §9) | H11: ≤ RTO
A12: KPI-08 | B12: Fournisseurs critiques évalués | C12: Structurer la sécurité des fournisseurs | D12: Fournisseurs critiques évalués ÷ fournisseurs critiques | E12: Grille d'évaluation fournisseurs | F12: Annuelle | G12: Non mesuré (grille non appliquée aux historiques, §10) | H12: 100 %
A13: KPI-09 | B13: Actions correctives closes dans les délais | C13: Amélioration continue | D13: Actions closes à l'échéance ÷ actions échues | E13: Registre des actions | F13: Mensuelle | G13: Non mesuré (plans d'action non clos, §9 et §12) | H13: À définir
A14: KPI-10 | B14: Taux de clic et de signalement lors des simulations de phishing | C14: Sensibiliser le personnel | D14: Clics ÷ envois ; signalements ÷ envois | E14: Plateforme de simulation | F14: À chaque campagne | G14: Non communiqué dans le cas | H14: À définir
